Workbook

Sheet Sheet1
B1: Unnamed: 0 | C1: 행정동 | D1: 시군구 | E1: 시설수 | F1: 시도명 | G1: 합계 | H1: 지수 | I1: 지수(정규화후) | J1: 가중치 | K1: 최종 | P1: 최종 | R1: 진짜최종
A2: 0 | B2: 0 | C2: 가리봉동 | D2: 구로구 | E2: 1 | F2: 서울특별시 | G2: 8746 | H2: 0.11433798 | I2: 0.11361029 | J2: 0.0050215749 | K2: 11.361029 | L2: =MAX(H:H) -> 0.4 | M2: =MIN(H:H) -> 0 | N2: =(H2-M2)/(L2-M2) -> 0.28584496 | O2: =N2*0.0442 -> 0.012634347 | P2: =O2*100 -> 1.2634347 | Q2: =VLOOKUP(C2,Sheet2!A:AU,47,0) -> 7.6674184 | R2: =IFERROR((P2+Q2),0) -> 8.9308531
A3: 1 | B3: 1 | C3: 가산동 | D3: 금천구 | E3: 1 | F3: 서울특별시 | G3: 25415 | H3: 0.039346842 | I3: 0.026299458 | J3: 0.001162436 | K3: 2.6299458 | L3: =MAX(H:H) -> 0.4 | M3: =MIN(H:H) -> 0 | N3: =(H3-M3)/(L3-M3) -> 0.098367106 | O3: =N3*0.0442 -> 0.0043478261 | P3: =O3*100 -> 0.43478261 | Q3: =VLOOKUP(C3,Sheet2!A:AU,47,0) -> 2.498492 | R3: =IFERROR((P3+Q3),0) -> 2.9332747
A4: 2 | B4: 2 | C4: 가정1동 | D4: 서구 | E4: 1 | F4: 인천광역시 | G4: 41263 | H4: 0.024234787 | I4: 0.0087047635 | J4: 0.00038475055 | K4: 0.87047635 | L4: =MAX(H:H) -> 0.4 | M4: =MIN(H:H) -> 0 | N4: =(H4-M4)/(L4-M4) -> 0.060586967 | O4: =N4*0.0442 -> 0.0026779439 | P4: =O4*100 -> 0.26779439 | Q4: =VLOOKUP(C4,Sheet2!A:AU,47,0) -> 0.07509207 | R4: =IFERROR((P4+Q4),0) -> 0.34288646
A5: 3 | B5: 3 | C5: 가좌1동 | D5: 서구 | E5: 3 | F5: 인천광역시 | G5: 12291 | H5: 0.24408103 | I5: 0.26466779 | J5: 0.011698316 | K5: 26.466779 | L5: =MAX(H:H) -> 0.4 | M5: =MIN(H:H) -> 0 | N5: =(H5-M5)/(L5-M5) -> 0.61020259 | O5: =N5*0.0442 -> 0.026970954 | P5: =O5*100 -> 2.6970954 | Q5: =VLOOKUP(C5,Sheet2!A:AU,47,0) -> 7.0592418 | R5: =IFERROR((P5+Q5),0) -> 9.7563372
A6: 4 | B6: 4 | C6: 가좌2동 | D6: 서구 | E6: 2 | F6: 인천광역시 | G6: 18007 | H6: 0.11106792 | I6: 0.10980301 | J6: 0.0048532932 | K6: 10.980301 | L6: =MAX(H:H) -> 0.4 | M6: =MIN(H:H) -> 0 | N6: =(H6-M6)/(L6-M6) -> 0.2776698 | O6: =N6*0.0442 -> 0.012273005 | P6: =O6*100 -> 1.2273005 | Q6: =VLOOKUP(C6,Sheet2!A:AU,47,0) -> 2.3233593 | R6: =IFERROR((P6+Q6),0) -> 3.5506598
A7: 5 | B7: 5 | C7: 가좌3동 | D7: 서구 | E7: 3 | F7: 인천광역시 | G7: 14862 | H7: 0.20185709 | I7: 0.2155072 | J7: 0.0095254184 | K7: 21.55072 | L7: =MAX(H:H) -> 0.4 | M7: =MIN(H:H) -> 0 | N7: =(H7-M7)/(L7-M7) -> 0.50464271 | O7: =N7*0.0442 -> 0.022305208 | P7: =O7*100 -> 2.2305208 | Q7: =VLOOKUP(C7,Sheet2!A:AU,47,0) -> 6.9826021 | R7: =IFERROR((P7+Q7),0) -> 9.2131229
A8: 6 | B8: 6 | C8: 가좌4동 | D8: 서구 | E8: 3 | F8: 인천광역시 | G8: 12134 | H8: 0.24723916 | I8: 0.26834474 | J8: 0.011860837 | K8: 26.834474 | L8: =MAX(H:H) -> 0.4 | M8: =MIN(H:H) -> 0 | N8: =(H8-M8)/(L8-M8) -> 0.61809791 | O8: =N8*0.0442 -> 0.027319927 | P8: =O8*100 -> 2.7319927 | Q8: =VLOOKUP(C8,Sheet2!A:AU,47,0) -> 5.3105193 | R8: =IFERROR((P8+Q8),0) -> 8.0425121
A9: 7 | B9: 7 | C9: 가좌동 | D9: 고양시 일산서구 | E9: 1 | F9: 경기도 | G9: 18108 | H9: 0.05522421 | I9: 0.044785191 | J9: 0.0019795054 | K9: 4.4785191 | L9: =MAX(H:H) -> 0.4 | M9: =MIN(H:H) -> 0 | N9: =(H9-M9)/(L9-M9) -> 0.13806053 | O9: =N9*0.0442 -> 0.0061022752 | P9: =O9*100 -> 0.61022752 | Q9: =VLOOKUP(C9,Sheet2!A:AU,47,0) -> 0.83454003 | R9: =IFERROR((P9+Q9),0) -> 1.4447676
A10: 8 | B10: 8 | C10: 간석1동 | D10: 남동구 | E10: 2 | F10: 인천광역시 | G10: 18135 | H10: 0.11028398 | I10: 0.10889029 | J10: 0.0048129508 | K10: 10.889029 | L10: =MAX(H:H) -> 0.4 | M10: =MIN(H:H) -> 0 | N10: =(H10-M10)/(L10-M10) -> 0.27570995 | O10: =N10*0.0442 -> 0.01218638 | P10: =O10*100 -> 1.218638 | Q10: =VLOOKUP(C10,Sheet2!A:AU,47,0) -> 3.0614189 | R10: =IFERROR((P10+Q10),0) -> 4.2800569
A11: 9 | B11: 9 | C11: 간석2동 | D11: 남동구 | E11: 2 | F11: 인천광역시 | G11: 20388 | H11: 0.09809692 | I11: 0.094701114 | J11: 0.0041857892 | K11: 9.4701114 | L11: =MAX(H:H) -> 0.4 | M11: =MIN(H:H) -> 0 | N11: =(H11-M11)/(L11-M11) -> 0.2452423 | O11: =N11*0.0442 -> 0.01083971 | P11: =O11*100 -> 1.083971 | Q11: =VLOOKUP(C11,Sheet2!A:AU,47,0) -> 1.7994111 | R11: =IFERROR((P11+Q11),0) -> 2.8833821
A12: 10 | B12: 10 | C12: 간석3동 | D12: 남동구 | E12: 1 | F12: 인천광역시 | G12: 24734 | H12: 0.040430177 | I12: 0.027560765 | J12: 0.0012181858 | K12: 2.7560765 | L12: =MAX(H:H) -> 0.4 | M12: =MIN(H:H) -> 0 | N12: =(H12-M12)/(L12-M12) -> 0.10107544 | O12: =N12*0.0442 -> 0.0044675346 | P12: =O12*100 -> 0.44675346 | Q12: =VLOOKUP(C12,Sheet2!A:AU,47,0) -> 0.88338055 | R12: =IFERROR((P12+Q12),0) -> 1.330134
A13: 11 | B13: 11 | C13: 간석4동 | D13: 남동구 | E13: 3 | F13: 인천광역시 | G13: 27702 | H13: 0.10829543 | I13: 0.10657506 | J13: 0.0047106174 | K13: 10.657506 | L13: =MAX(H:H) -> 0.4 | M13: =MIN(H:H) -> 0 | N13: =(H13-M13)/(L13-M13) -> 0.27073857 | O13: =N13*0.0442 -> 0.011966645 | P13: =O13*100 -> 1.1966645 | Q13: =VLOOKUP(C13,Sheet2!A:AU,47,0) -> 2.530954 | R13: =IFERROR((P13+Q13),0) -> 3.7276185
... A221: 219 | B221: 219 | C221: 상봉2동 | D221: 중랑구 | E221: 1 | F221: 서울특별시 | G221: 21554 | H221: 0.046395101 | I221: 0.034505618 | J221: 0.0015251483 | K221: 3.4505618 | L221: =MAX(H:H) -> 0.4 | M221: =MIN(H:H) -> 0 | N221: =(H221-M221)/(L221-M221) -> 0.11598775 | O221: =N221*0.0442 -> 0.0051266586 | P221: =O221*100 -> 0.51266586 | Q221: =VLOOKUP(C221,Sheet2!A:AU,47,0) -> 2.0060118 | R221: =IFERROR((P221+Q221),0) -> 2.5186776
A222: 220 | B222: 220 | C222: 상암동 | D222: 강서구 | E222: 1 | L222: =MAX(H:H) -> 0.4 | M222: =MIN(H:H) -> 0 | N222: =(H222-M222)/(L222-M222) -> 0 | O222: =N222*0.0442 -> 0 | P222: =O222*100 -> 0 | Q222: =VLOOKUP(C222,Sheet2!A:AU,47,0) -> 0.33743396 | R222: =IFERROR((P222+Q222),0) -> 0.33743396
A223: 221 | B223: 221 | C223: 상암동 | D223: 관악구 | E223: 1 | L223: =MAX(H:H) -> 0.4 | M223: =MIN(H:H) -> 0 | N223: =(H223-M223)/(L223-M223) -> 0 | O223: =N223*0.0442 -> 0 | P223: =O223*100 -> 0 | Q223: =VLOOKUP(C223,Sheet2!A:AU,47,0) -> 0.33743396 | R223: =IFERROR((P223+Q223),0) -> 0.33743396
A224: 222 | B224: 222 | C224: 상암동 | D224: 마포구 | E224: 1 | F224: 서울특별시 | G224: 29076 | H224: 0.034392626 | I224: 0.020531353 | J224: 0.00090748581 | K224: 2.0531353 | L224: =MAX(H:H) -> 0.4 | M224: =MIN(H:H) -> 0 | N224: =(H224-M224)/(L224-M224) -> 0.085981566 | O224: =N224*0.0442 -> 0.0038003852 | P224: =O224*100 -> 0.38003852 | Q224: =VLOOKUP(C224,Sheet2!A:AU,47,0) -> 0.33743396 | R224: =IFERROR((P224+Q224),0) -> 0.71747248
A225: 223 | B225: 223 | C225: 상암동 | D225: 중랑구 | E225: 1 | L225: =MAX(H:H) -> 0.4 | M225: =MIN(H:H) -> 0 | N225: =(H225-M225)/(L225-M225) -> 0 | O225: =N225*0.0442 -> 0 | P225: =O225*100 -> 0 | Q225: =VLOOKUP(C225,Sheet2!A:AU,47,0) -> 0.33743396 | R225: =IFERROR((P225+Q225),0) -> 0.33743396
A226: 224 | B226: 224 | C226: 상일2동 | D226: 강동구 | E226: 1 | F226: 서울특별시 | G226: 13268 | H226: 0.07536931 | I226: 0.068239767 | J226: 0.0030161977 | K226: 6.8239767 | L226: =MAX(H:H) -> 0.4 | M226: =MIN(H:H) -> 0 | N226: =(H226-M226)/(L226-M226) -> 0.18842327 | O226: =N226*0.0442 -> 0.0083283087 | P226: =O226*100 -> 0.83283087 | Q226: =VLOOKUP(C226,Sheet2!A:AU,47,0) -> 0.79329734 | R226: =IFERROR((P226+Q226),0) -> 1.6261282
A227: 225 | B227: 225 | C227: 상하동 | D227: 용인시 기흥구 | E227: 2 | F227: 경기도 | G227: 22890 | H227: 0.087374399 | I227: 0.082217076 | J227: 0.0036339948 | K227: 8.2217076 | L227: =MAX(H:H) -> 0.4 | M227: =MIN(H:H) -> 0 | N227: =(H227-M227)/(L227-M227) -> 0.218436 | O227: =N227*0.0442 -> 0.0096548711 | P227: =O227*100 -> 0.96548711 | Q227: =VLOOKUP(C227,Sheet2!A:AU,47,0) -> 1.5772133 | R227: =IFERROR((P227+Q227),0) -> 2.5427004
A228: 226 | B228: 226 | C228: 상현3동 | D228: 용인시 수지구 | E228: 1 | F228: 경기도 | G228: 27196 | H228: 0.036770113 | I228: 0.023299418 | J228: 0.0010298343 | K228: 2.3299418 | L228: =MAX(H:H) -> 0.4 | M228: =MIN(H:H) -> 0 | N228: =(H228-M228)/(L228-M228) -> 0.091925283 | O228: =N228*0.0442 -> 0.0040630975 | P228: =O228*100 -> 0.40630975 | Q228: =VLOOKUP(C228,Sheet2!A:AU,47,0) -> 0.29358459 | R228: =IFERROR((P228+Q228),0) -> 0.69989434
A229: 227 | B229: 227 | C229: 서교동 | D229: 마포구 | E229: 1 | F229: 서울특별시 | G229: 23472 | H229: 0.042603954 | I229: 0.030091654 | J229: 0.0013300511 | K229: 3.0091654 | L229: =MAX(H:H) -> 0.4 | M229: =MIN(H:H) -> 0 | N229: =(H229-M229)/(L229-M229) -> 0.10650988 | O229: =N229*0.0442 -> 0.0047077369 | P229: =O229*100 -> 0.47077369 | Q229: =VLOOKUP(C229,Sheet2!A:AU,47,0) -> 1.7610538 | R229: =IFERROR((P229+Q229),0) -> 2.2318275
A230: 228 | B230: 228 | C230: 서농동 | D230: 용인시 기흥구 | E230: 1 | F230: 경기도 | G230: 24409 | H230: 0.040968495 | I230: 0.028187519 | J230: 0.0012458883 | K230: 2.8187519 | L230: =MAX(H:H) -> 0.4 | M230: =MIN(H:H) -> 0 | N230: =(H230-M230)/(L230-M230) -> 0.10242124 | O230: =N230*0.0442 -> 0.0045270187 | P230: =O230*100 -> 0.45270187 | Q230: =VLOOKUP(C230,Sheet2!A:AU,47,0) -> 0.35769893 | R230: =IFERROR((P230+Q230),0) -> 0.8104008
A231: 229 | B231: 229 | C231: 서림동 | D231: 관악구 | E231: 2 | F231: 서울특별시 | G231: 23612 | H231: 0.084702694 | I231: 0.079106458 | J231: 0.0034965054 | K231: 7.9106458 | L231: =MAX(H:H) -> 0.4 | M231: =MIN(H:H) -> 0 | N231: =(H231-M231)/(L231-M231) -> 0.21175673 | O231: =N231*0.0442 -> 0.0093596476 | P231: =O231*100 -> 0.93596476 | Q231: =VLOOKUP(C231,Sheet2!A:AU,47,0) -> 4.1773863 | R231: =IFERROR((P231+Q231),0) -> 5.1133511
A232: 230 | B232: 230 | C232: 서원동 | D232: 관악구 | E232: 1 | F232: 서울특별시 | G232: 22832 | H232: 0.043798178 | I232: 0.031482067 | J232: 0.0013915074 | K232: 3.1482067 | L232: =MAX(H:H) -> 0.4 | M232: =MIN(H:H) -> 0 | N232: =(H232-M232)/(L232-M232) -> 0.10949544 | O232: =N232*0.0442 -> 0.0048396987 | P232: =O232*100 -> 0.48396987 | Q232: =VLOOKUP(C232,Sheet2!A:AU,47,0) -> 2.6432109 | R232: =IFERROR((P232+Q232),0) -> 3.1271808
A233: 231 | B233: 231 | C233: 서창2동 | D233: 남동구 | E233: 1 | F233: 인천광역시 | G233: 37436 | H233: 0.026712256 | I233: 0.011589236 | J233: 0.00051224423 | K233: 1.1589236 | L233: =MAX(H:H) -> 0.4 | M233: =MIN(H:H) -> 0 | N233: =(H233-M233)/(L233-M233) -> 0.066780639 | O233: =N233*0.0442 -> 0.0029517042 | P233: =O233*100 -> 0.29517042 | Q233: =VLOOKUP(C233,Sheet2!A:AU,47,0) -> 0.090754647 | R233: =IFERROR((P233+Q233),0) -> 0.38592507
A234: 232 | B234: 232 | C234: 석관동 | D234: 성북구 | E234: 1 | F234: 서울특별시 | G234: 32781 | H234: 0.030505476 | I234: 0.016005614 | J234: 0.00070744813 | K234: 1.6005614 | L234: =MAX(H:H) -> 0.4 | M234: =MIN(H:H) -> 0 | N234: =(H234-M234)/(L234-M234) -> 0.076263689 | O234: =N234*0.0442 -> 0.0033708551 | P234: =O234*100 -> 0.33708551 | Q234: =VLOOKUP(C234,Sheet2!A:AU,47,0) -> 0.66761171 | R234: =IFERROR((P234+Q234),0) -> 1.0046972
A235: 233 | B235: 233 | C235: 석남1동 | D235: 서구 | E235: 2 | F235: 인천광역시 | G235: 19690 | H235: 0.1015744 | I235: 0.098749885 | J235: 0.0043647449 | K235: 9.8749885 | L235: =MAX(H:H) -> 0.4 | M235: =MIN(H:H) -> 0 | N235: =(H235-M235)/(L235-M235) -> 0.25393601 | O235: =N235*0.0442 -> 0.011223972 | P235: =O235*100 -> 1.1223972 | Q235: =VLOOKUP(C235,Sheet2!A:AU,47,0) -> 2.9892598 | R235: =IFERROR((P235+Q235),0) -> 4.1116569
A236: 234 | B236: 234 | C236: 석남3동 | D236: 서구 | E236: 4 | F236: 인천광역시 | G236: 12982 | H236: 0.30811893 | I236: 0.33922596 | J236: 0.014993787 | K236: 33.922596 | L236: =MAX(H:H) -> 0.4 | M236: =MIN(H:H) -> 0 | N236: =(H236-M236)/(L236-M236) -> 0.77029733 | O236: =N236*0.0442 -> 0.034047142 | P236: =O236*100 -> 3.4047142 | Q236: =VLOOKUP(C236,Sheet2!A:AU,47,0) -> 8.04 | R236: =IFERROR((P236+Q236),0) -> 11.444714
A237: 235 | B237: 235 | C237: 석수2동 | D237: 안양시 만안구 | E237: 2 | F237: 경기도 | G237: 28694 | H237: 0.069700983 | I237: 0.061640236 | J237: 0.0027244984 | K237: 6.1640236 | L237: =MAX(H:H) -> 0.4 | M237: =MIN(H:H) -> 0 | N237: =(H237-M237)/(L237-M237) -> 0.17425246 | O237: =N237*0.0442 -> 0.0077019586 | P237: =O237*100 -> 0.77019586 | Q237: =VLOOKUP(C237,Sheet2!A:AU,47,0) -> 1.5314206 | R237: =IFERROR((P237+Q237),0) -> 2.3016164
... A500: 498 | B500: 498 | C500: 흑석동 | D500: 동작구 | E500: 4 | F500: 서울특별시 | G500: 29825 | H500: 0.13411567 | I500: 0.1366371 | J500: 0.0060393599 | K500: 13.66371 | L500: =MAX(H:H) -> 0.4 | M500: =MIN(H:H) -> 0 | N500: =(H500-M500)/(L500-M500) -> 0.33528919 | O500: =N500*0.0442 -> 0.014819782 | P500: =O500*100 -> 1.4819782 | Q500: =VLOOKUP(C500,Sheet2!A:AU,47,0) -> 2.4439048 | R500: =IFERROR((P500+Q500),0) -> 3.925883
A501: 499 | B501: 0 | C501: 청운효자동 | D501: 종로구 | E501: 0 | F501: 0 | G501: 0 | H501: 0 | I501: 0 | J501: 0 | K501: 0 | L501: =MAX(H:H) -> 0.4 | M501: =MIN(H:H) -> 0 | N501: =(H501-M501)/(L501-M501) -> 0 | O501: =N501*0.0442 -> 0 | P501: =O501*100 -> 0 | Q501: =VLOOKUP(C501,Sheet2!A:AU,47,0) -> #N/A | R501: =IFERROR((P501+Q501),0) -> 0
A502: 500 | B502: 0 | C502: 사직동 | D502: 종로구 | E502: 0 | F502: 0 | G502: 0 | H502: 0 | I502: 0 | J502: 0 | K502: 0 | L502: =MAX(H:H) -> 0.4 | M502: =MIN(H:H) -> 0 | N502: =(H502-M502)/(L502-M502) -> 0 | O502: =N502*0.0442 -> 0 | P502: =O502*100 -> 0 | Q502: =VLOOKUP(C502,Sheet2!A:AU,47,0) -> #N/A | R502: =IFERROR((P502+Q502),0) -> 0
A503: 501 | B503: 0 | C503: 삼청동 | D503: 종로구 | E503: 0 | F503: 0 | G503: 0 | H503: 0 | I503: 0 | J503: 0 | K503: 0 | L503: =MAX(H:H) -> 0.4 | M503: =MIN(H:H) -> 0 | N503: =(H503-M503)/(L503-M503) -> 0 | O503: =N503*0.0442 -> 0 | P503: =O503*100 -> 0 | Q503: =VLOOKUP(C503,Sheet2!A:AU,47,0) -> #N/A | R503: =IFERROR((P503+Q503),0) -> 0
A504: 502 | B504: 0 | C504: 부암동 | D504: 종로구 | E504: 0 | F504: 0 | G504: 0 | H504: 0 | I504: 0 | J504: 0 | K504: 0 | L504: =MAX(H:H) -> 0.4 | M504: =MIN(H:H) -> 0 | N504: =(H504-M504)/(L504-M504) -> 0 | O504: =N504*0.0442 -> 0 | P504: =O504*100 -> 0 | Q504: =VLOOKUP(C504,Sheet2!A:AU,47,0) -> #N/A | R504: =IFERROR((P504+Q504),0) -> 0
A505: 503 | B505: 0 | C505: 평창동 | D505: 종로구 | E505: 0 | F505: 0 | G505: 0 | H505: 0 | I505: 0 | J505: 0 | K505: 0 | L505: =MAX(H:H) -> 0.4 | M505: =MIN(H:H) -> 0 | N505: =(H505-M505)/(L505-M505) -> 0 | O505: =N505*0.0442 -> 0 | P505: =O505*100 -> 0 | Q505: =VLOOKUP(C505,Sheet2!A:AU,47,0) -> #N/A | R505: =IFERROR((P505+Q505),0) -> 0
A506: 504 | B506: 0 | C506: 교남동 | D506: 종로구 | E506: 0 | F506: 0 | G506: 0 | H506: 0 | I506: 0 | J506: 0 | K506: 0 | L506: =MAX(H:H) -> 0.4 | M506: =MIN(H:H) -> 0 | N506: =(H506-M506)/(L506-M506) -> 0 | O506: =N506*0.0442 -> 0 | P506: =O506*100 -> 0 | Q506: =VLOOKUP(C506,Sheet2!A:AU,47,0) -> #N/A | R506: =IFERROR((P506+Q506),0) -> 0
A507: 505 | B507: 0 | C507: 가회동 | D507: 종로구 | E507: 0 | F507: 0 | G507: 0 | H507: 0 | I507: 0 | J507: 0 | K507: 0 | L507: =MAX(H:H) -> 0.4 | M507: =MIN(H:H) -> 0 | N507: =(H507-M507)/(L507-M507) -> 0 | O507: =N507*0.0442 -> 0 | P507: =O507*100 -> 0 | Q507: =VLOOKUP(C507,Sheet2!A:AU,47,0) -> #N/A | R507: =IFERROR((P507+Q507),0) -> 0
A508: 506 | B508: 0 | C508: 종로1.2.3.4가동 | D508: 종로구 | E508: 0 | F508: 0 | G508: 0 | H508: 0 | I508: 0 | J508: 0 | K508: 0 | L508: =MAX(H:H) -> 0.4 | M508: =MIN(H:H) -> 0 | N508: =(H508-M508)/(L508-M508) -> 0 | O508: =N508*0.0442 -> 0 | P508: =O508*100 -> 0 | Q508: =VLOOKUP(C508,Sheet2!A:AU,47,0) -> #N/A | R508: =IFERROR((P508+Q508),0) -> 0
A509: 507 | B509: 0 | C509: 혜화동 | D509: 종로구 | E509: 0 | F509: 0 | G509: 0 | H509: 0 | I509: 0 | J509: 0 | K509: 0 | L509: =MAX(H:H) -> 0.4 | M509: =MIN(H:H) -> 0 | N509: =(H509-M509)/(L509-M509) -> 0 | O509: =N509*0.0442 -> 0 | P509: =O509*100 -> 0 | Q509: =VLOOKUP(C509,Sheet2!A:AU,47,0) -> #N/A | R509: =IFERROR((P509+Q509),0) -> 0
...

Sheet Sheet2
A1: 행정동 | B1: 시군구 | C1: 시설수 | D1: 시도명 | E1: 0세남자 | F1: 1세남자 | G1: 2세남자 | H1: 3세남자 | I1: 4세남자 | J1: 5세남자 | K1: 6세남자 | L1: 7세남자 | M1: 8세남자 | N1: 9세남자 | O1: 10세남자 | P1: 11세남자 | Q1: 12세남자 | R1: 13세남자 | S1: 14세남자 | T1: 15세남자 | U1: 16세남자 | V1: 17세남자 | W1: 18세남자 | X1: 0세여자 | Y1: 1세여자 | Z1: 2세여자 | AA1: 3세여자 | AB1: 4세여자 | AC1: 5세여자 | AD1: 6세여자 | AE1: 7세여자 | AF1: 8세여자 | AG1: 9세여자 | AH1: 10세여자 | AI1: 11세여자 | AJ1: 12세여자 | AK1: 13세여자 | AL1: 14세여자 | AM1: 15세여자 | AN1: 16세여자 | AO1: 17세여자 | AP1: 18세여자 | AQ1: 합계 | AR1: 센터지수(정규화전) | AS1: 센터지수(정규화후) | AT1: 가중치 적용 | AU1: 최종
A2: 가리봉동 | B2: 구로구 | C2: 1 | D2: 서울특별시 | E2: 17 | F2: 9 | G2: 10 | H2: 3 | I2: 9 | J2: 7 | K2: 4 | L2: 6 | M2: 10 | N2: 10 | O2: 13 | P2: 14 | Q2: 10 | R2: 11 | S2: 9 | T2: 12 | U2: 12 | V2: 10 | W2: 18 | X2: 8 | Y2: 8 | Z2: 3 | AA2: 8 | AB2: 7 | AC2: 5 | AD2: 11 | AE2: 3 | AF2: 7 | AG2: 10 | AH2: 10 | AI2: 7 | AJ2: 10 | AK2: 6 | AL2: 8 | AM2: 13 | AN2: 11 | AO2: 7 | AP2: 13 | AQ2: 349 | AR2: 2.8653295 | AS2: =(AR2-AW2)/(AV2-AW2) -> 0.95365901 | AT2: =AS2*0.0804 -> 0.076674184 | AU2: =AT2*100 -> 7.6674184 | AV2: =MAX(AR:AR) -> 3 | AW2: =MIN(AR:AR) -> 0.093923171
A3: 가산동 | B3: 금천구 | C3: 1 | D3: 서울특별시 | E3: 52 | F3: 35 | G3: 31 | H3: 23 | I3: 25 | J3: 27 | K3: 16 | L3: 25 | M3: 22 | N3: 24 | O3: 24 | P3: 25 | Q3: 28 | R3: 19 | S3: 14 | T3: 17 | U3: 33 | V3: 31 | W3: 42 | X3: 52 | Y3: 33 | Z3: 26 | AA3: 22 | AB3: 19 | AC3: 19 | AD3: 21 | AE3: 13 | AF3: 26 | AG3: 27 | AH3: 27 | AI3: 24 | AJ3: 23 | AK3: 25 | AL3: 26 | AM3: 18 | AN3: 29 | AO3: 28 | AP3: 32 | AQ3: 1003 | AR3: 0.99700897 | AS3: =(AR3-AW3)/(AV3-AW3) -> 0.31075772 | AT3: =AS3*0.0804 -> 0.02498492 | AU3: =AT3*100 -> 2.498492 | AV3: =MAX(AR:AR) -> 3 | AW3: =MIN(AR:AR) -> 0.093923171
A4: 가정1동 | B4: 서구 | C4: 1 | D4: 인천광역시 | E4: 172 | F4: 180 | G4: 170 | H4: 200 | I4: 210 | J4: 224 | K4: 247 | L4: 253 | M4: 289 | N4: 276 | O4: 328 | P4: 259 | Q4: 273 | R4: 264 | S4: 216 | T4: 184 | U4: 180 | V4: 147 | W4: 163 | X4: 175 | Y4: 213 | Z4: 191 | AA4: 183 | AB4: 185 | AC4: 189 | AD4: 226 | AE4: 253 | AF4: 252 | AG4: 278 | AH4: 281 | AI4: 254 | AJ4: 231 | AK4: 240 | AL4: 228 | AM4: 155 | AN4: 172 | AO4: 154 | AP4: 165 | AQ4: 8260 | AR4: 0.12106538 | AS4: =(AR4-AW4)/(AV4-AW4) -> 0.0093398097 | AT4: =AS4*0.0804 -> 0.0007509207 | AU4: =AT4*100 -> 0.07509207 | AV4: =MAX(AR:AR) -> 3 | AW4: =MIN(AR:AR) -> 0.093923171
A5: 가좌1동 | B5: 서구 | C5: 3 | D5: 인천광역시 | E5: 40 | F5: 43 | G5: 29 | H5: 27 | I5: 22 | J5: 23 | K5: 25 | L5: 26 | M5: 31 | N5: 29 | O5: 28 | P5: 36 | Q5: 34 | R5: 39 | S5: 27 | T5: 45 | U5: 33 | V5: 35 | W5: 43 | X5: 43 | Y5: 36 | Z5: 20 | AA5: 16 | AB5: 21 | AC5: 21 | AD5: 21 | AE5: 23 | AF5: 23 | AG5: 25 | AH5: 23 | AI5: 33 | AJ5: 24 | AK5: 25 | AL5: 30 | AM5: 33 | AN5: 22 | AO5: 38 | AP5: 42 | AQ5: 1134 | AR5: 2.6455026 | AS5: =(AR5-AW5)/(AV5-AW5) -> 0.87801515 | AT5: =AS5*0.0804 -> 0.070592418 | AU5: =AT5*100 -> 7.0592418 | AV5: =MAX(AR:AR) -> 3 | AW5: =MIN(AR:AR) -> 0.093923171
A6: 가좌2동 | B6: 서구 | C6: 2 | D6: 인천광역시 | E6: 49 | F6: 51 | G6: 33 | H6: 39 | I6: 32 | J6: 48 | K6: 43 | L6: 37 | M6: 42 | N6: 49 | O6: 61 | P6: 78 | Q6: 71 | R6: 75 | S6: 91 | T6: 90 | U6: 79 | V6: 75 | W6: 83 | X6: 45 | Y6: 39 | Z6: 21 | AA6: 37 | AB6: 40 | AC6: 24 | AD6: 36 | AE6: 37 | AF6: 46 | AG6: 57 | AH6: 59 | AI6: 41 | AJ6: 62 | AK6: 69 | AL6: 78 | AM6: 78 | AN6: 78 | AO6: 86 | AP6: 83 | AQ6: 2142 | AR6: 0.93370682 | AS6: =(AR6-AW6)/(AV6-AW6) -> 0.28897503 | AT6: =AS6*0.0804 -> 0.023233593 | AU6: =AT6*100 -> 2.3233593 | AV6: =MAX(AR:AR) -> 3 | AW6: =MIN(AR:AR) -> 0.093923171
A7: 가좌3동 | B7: 서구 | C7: 3 | D7: 인천광역시 | E7: 21 | F7: 9 | G7: 23 | H7: 15 | I7: 19 | J7: 33 | K7: 15 | L7: 20 | M7: 21 | N7: 22 | O7: 30 | P7: 36 | Q7: 40 | R7: 40 | S7: 40 | T7: 42 | U7: 42 | V7: 40 | W7: 68 | X7: 24 | Y7: 16 | Z7: 16 | AA7: 14 | AB7: 18 | AC7: 24 | AD7: 16 | AE7: 24 | AF7: 20 | AG7: 27 | AH7: 28 | AI7: 46 | AJ7: 32 | AK7: 38 | AL7: 43 | AM7: 35 | AN7: 48 | AO7: 53 | AP7: 48 | AQ7: 1146 | AR7: 2.617801 | AS7: =(AR7-AW7)/(AV7-AW7) -> 0.86848285 | AT7: =AS7*0.0804 -> 0.069826021 | AU7: =AT7*100 -> 6.9826021 | AV7: =MAX(AR:AR) -> 3 | AW7: =MIN(AR:AR) -> 0.093923171
A8: 가좌4동 | B8: 서구 | C8: 3 | D8: 인천광역시 | E8: 44 | F8: 41 | G8: 31 | H8: 43 | I8: 36 | J8: 38 | K8: 46 | L8: 34 | M8: 42 | N8: 50 | O8: 41 | P8: 38 | Q8: 36 | R8: 32 | S8: 36 | T8: 38 | U8: 42 | V8: 37 | W8: 43 | X8: 43 | Y8: 41 | Z8: 39 | AA8: 36 | AB8: 37 | AC8: 43 | AD8: 34 | AE8: 39 | AF8: 23 | AG8: 37 | AH8: 48 | AI8: 34 | AJ8: 39 | AK8: 45 | AL8: 39 | AM8: 47 | AN8: 38 | AO8: 43 | AP8: 37 | AQ8: 1490 | AR8: 2.0134228 | AS8: =(AR8-AW8)/(AV8-AW8) -> 0.66051235 | AT8: =AS8*0.0804 -> 0.053105193 | AU8: =AT8*100 -> 5.3105193 | AV8: =MAX(AR:AR) -> 3 | AW8: =MIN(AR:AR) -> 0.093923171
A9: 가좌동 | B9: 고양시 일산서구 | C9: 1 | D9: 경기도 | E9: 25 | F9: 33 | G9: 25 | H9: 25 | I9: 44 | J9: 33 | K9: 43 | L9: 49 | M9: 41 | N9: 58 | O9: 71 | P9: 79 | Q9: 88 | R9: 110 | S9: 96 | T9: 96 | U9: 103 | V9: 93 | W9: 124 | X9: 25 | Y9: 29 | Z9: 24 | AA9: 28 | AB9: 33 | AC9: 38 | AD9: 37 | AE9: 49 | AF9: 54 | AG9: 72 | AH9: 63 | AI9: 74 | AJ9: 90 | AK9: 111 | AL9: 103 | AM9: 111 | AN9: 111 | AO9: 110 | AP9: 130 | AQ9: 2528 | AR9: 0.39556962 | AS9: =(AR9-AW9)/(AV9-AW9) -> 0.10379851 | AT9: =AS9*0.0804 -> 0.0083454003 | AU9: =AT9*100 -> 0.83454003 | AV9: =MAX(AR:AR) -> 3 | AW9: =MIN(AR:AR) -> 0.093923171
A10: 간석1동 | B10: 남동구 | C10: 2 | D10: 인천광역시 | E10: 45 | F10: 31 | G10: 30 | H10: 27 | I10: 17 | J10: 38 | K10: 27 | L10: 43 | M10: 30 | N10: 42 | O10: 42 | P10: 61 | Q10: 51 | R10: 61 | S10: 59 | T10: 72 | U10: 48 | V10: 65 | W10: 70 | X10: 55 | Y10: 28 | Z10: 32 | AA10: 22 | AB10: 32 | AC10: 28 | AD10: 26 | AE10: 28 | AF10: 34 | AG10: 37 | AH10: 43 | AI10: 45 | AJ10: 43 | AK10: 53 | AL10: 54 | AM10: 59 | AN10: 60 | AO10: 62 | AP10: 66 | AQ10: 1666 | AR10: 1.2004802 | AS10: =(AR10-AW10)/(AV10-AW10) -> 0.38077349 | AT10: =AS10*0.0804 -> 0.030614189 | AU10: =AT10*100 -> 3.0614189 | AV10: =MAX(AR:AR) -> 3 | AW10: =MIN(AR:AR) -> 0.093923171
A11: 간석2동 | B11: 남동구 | C11: 2 | D11: 인천광역시 | E11: 43 | F11: 34 | G11: 31 | H11: 48 | I11: 43 | J11: 44 | K11: 52 | L11: 57 | M11: 68 | N11: 76 | O11: 99 | P11: 72 | Q11: 102 | R11: 117 | S11: 91 | T11: 108 | U11: 116 | V11: 103 | W11: 123 | X11: 34 | Y11: 31 | Z11: 34 | AA11: 37 | AB11: 39 | AC11: 42 | AD11: 41 | AE11: 57 | AF11: 57 | AG11: 67 | AH11: 77 | AI11: 99 | AJ11: 67 | AK11: 98 | AL11: 95 | AM11: 106 | AN11: 81 | AO11: 101 | AP11: 97 | AQ11: 2687 | AR11: 0.74432453 | AS11: =(AR11-AW11)/(AV11-AW11) -> 0.22380735 | AT11: =AS11*0.0804 -> 0.017994111 | AU11: =AT11*100 -> 1.7994111 | AV11: =MAX(AR:AR) -> 3 | AW11: =MIN(AR:AR) -> 0.093923171
A12: 간석3동 | B12: 남동구 | C12: 1 | D12: 인천광역시 | E12: 42 | F12: 44 | G12: 46 | H12: 63 | I12: 44 | J12: 44 | K12: 46 | L12: 59 | M12: 56 | N12: 53 | O12: 80 | P12: 81 | Q12: 69 | R12: 87 | S12: 80 | T12: 82 | U12: 102 | V12: 95 | W12: 95 | X12: 41 | Y12: 43 | Z12: 29 | AA12: 35 | AB12: 30 | AC12: 44 | AD12: 34 | AE12: 44 | AF12: 69 | AG12: 60 | AH12: 79 | AI12: 59 | AJ12: 67 | AK12: 84 | AL12: 87 | AM12: 89 | AN12: 88 | AO12: 81 | AP12: 89 | AQ12: 2420 | AR12: 0.41322314 | AS12: =(AR12-AW12)/(AV12-AW12) -> 0.1098732 | AT12: =AS12*0.0804 -> 0.0088338055 | AU12: =AT12*100 -> 0.88338055 | AV12: =MAX(AR:AR) -> 3 | AW12: =MIN(AR:AR) -> 0.093923171
A13: 간석4동 | B13: 남동구 | C13: 3 | D13: 인천광역시 | E13: 56 | F13: 59 | G13: 45 | H13: 58 | I13: 45 | J13: 55 | K13: 53 | L13: 62 | M13: 56 | N13: 74 | O13: 101 | P13: 100 | Q13: 85 | R13: 103 | S13: 90 | T13: 102 | U13: 114 | V13: 105 | W13: 128 | X13: 60 | Y13: 59 | Z13: 49 | AA13: 48 | AB13: 54 | AC13: 57 | AD13: 52 | AE13: 68 | AF13: 68 | AG13: 81 | AH13: 74 | AI13: 97 | AJ13: 83 | AK13: 85 | AL13: 101 | AM13: 110 | AN13: 93 | AO13: 116 | AP13: 128 | AQ13: 2974 | AR13: 1.0087424 | AS13: =(AR13-AW13)/(AV13-AW13) -> 0.31479528 | AT13: =AS13*0.0804 -> 0.02530954 | AU13: =AT13*100 -> 2.530954 | AV13: =MAX(AR:AR) -> 3 | AW13: =MIN(AR:AR) -> 0.093923171
... A497: 흑석동 | B497: 동작구 | C497: 4 | D497: 서울특별시 | E497: 101 | F497: 82 | G497: 102 | H497: 100 | I497: 81 | J497: 101 | K497: 108 | L497: 117 | M497: 121 | N497: 127 | O497: 146 | P497: 123 | Q497: 125 | R497: 123 | S497: 107 | T497: 102 | U497: 88 | V497: 86 | W497: 120 | X497: 99 | Y497: 79 | Z497: 93 | AA497: 81 | AB497: 92 | AC497: 91 | AD497: 121 | AE497: 119 | AF497: 140 | AG497: 132 | AH497: 132 | AI497: 132 | AJ497: 107 | AK497: 124 | AL497: 109 | AM497: 94 | AN497: 91 | AO497: 93 | AP497: 104 | AQ497: 4093 | AR497: 0.97727828 | AS497: =(AR497-AW497)/(AV497-AW497) -> 0.30396826 | AT497: =AS497*0.0804 -> 0.024439048 | AU497: =AT497*100 -> 2.4439048 | AV497: =MAX(AR:AR) -> 3 | AW497: =MIN(AR:AR) -> 0.093923171
